Workbook

Sheet الاليات
A2: ت | B2: نوع الاليه | C2: رقمها | D2: الموديل | E2: المالك | F2: صلاحية السنوية | G2: تنبية صلاحية | H2: الموقع | I2: اسم السائق | J2: اخر عداد / ملاحظات | K2: المبلغ دينار | L2: المبلغ $
A3: المكتب الرئيسي بغداد / المنصور | G3: 46177
A4: 1 | B4: هونداي توسان ستيشن | C4: 88707 هـ بغداد | D4: 2018 | E4: شركة القبس للمقاولات | F4: =DATE(2028,7,18) -> 46952 | G4: =IF(F4<NOW(),"تنبية","") | H4: المقر | I4: خالد ياسين | J4: ='توسان 88707'!I5 -> 126000 | K4: ='توسان 88707'!F98 -> 2202500 | L4: ='توسان 88707'!G98 -> 0
A5: 2 | B5: تويوتا بيك اب | C5: 11 A 71993 | D5: 2019 | E5: شركة القبس للمقاولات | F5: 47406 | H5: المقر | I5: أبو مروان | J5: =' 11 A 71993 تويوتا بيك اب'!I5 -> 81700 | K5: =' 11 A 71993 تويوتا بيك اب'!F51 -> 2638000 | L5: =' 11 A 71993 تويوتا بيك اب'!G51 -> 0
A6: 3 | B6: شوفرليت تاهو | C6: 11 W 8011 | D6: 2021 | E6: خالد علي | F6: =DATE(2030,7,25) -> 47689 | G6: =IF(F6<NOW(),"تنبية","") | H6: المقر | I6: الإدارة | J6: ='11 W 8011 تاهو'!I5 -> 0 | K6: ='11 W 8011 تاهو'!F35 -> 6548500 | L6: ='11 W 8011 تاهو'!G35 -> 1440
A7: 4 | B7: تويوتا برادو | C7: 11733 د بغداد | D7: 2009 | E7: شركة القبس للمقاولات | F7: =DATE(2027,11,22) -> 46713 | G7: =IF(F7<NOW(),"تنبية","") | H7: المقر | I7: الإدارة | J7: 178000 | K7: ='برادو 2009'!F43 -> 4888250 | L7: ='2022 البرادو '!G54 -> 0
A8: 5 | B8: تويوتا برادو ستيشن | C8: 52164 ن بغداد | D8: 2022 | E8: تركي علي صالح | F8: =DATE(2026,11,3) -> 46329 | G8: =IF(F8<NOW(),"تنبية","") | H8: المقر | I8: الإدارة | J8: 28000 | K8: ='2022 البرادو '!F54 -> 2727000 | L8: ='برادو 2009'!G43 -> 0
A9: 6 | B9: جيب جراند شيروكي | C9: 11 L 41113 | D9: 2024 | E9: تركي علي صالح | F9: =DATE(2029,11,4) -> 47426 | G9: =IF(F9<NOW(),"تنبية","") | H9: المقر | I9: الإدارة | J9: ='جيب شيروكي '!I5 -> 12200 | K9: ='جيب شيروكي '!F36 -> 1126000 | L9: ='جيب شيروكي '!G36 -> 1700
A10: 7 | B10: تويوتا راف فور | C10: 11 Q 51965 | D10: 2024 | E10: شركة القبس للمقاولات | F10: =DATE(2027,11,3) -> 46694 | G10: =IF(F10<NOW(),"تنبية","") | H10: المقر | I10: الإدارة | J10: ='راف فور'!I5 -> 20000 | K10: ='راف فور'!F36 -> 667500 | L10: ='راف فور'!G36 -> 0
A11: البيكبات الحمل
A12: =A10+1 -> 8 | B12: تويوتا هايلوكس - بيك اب | C12: 28332 أ بغداد | D12: 2013 | E12: شركة سمو بغداد | F12: =DATE(2027,10,0) -> 46660 | G12: =IF(F12<NOW(),"تنبية","") | H12: خان ضاري | I12: م بكر | K12: ='تويوتا بكب 28332'!F55 -> 4612750 | L12: ='تويوتا بكب 28332'!G55 -> 0
A13: =A12+1 -> 9 | B13: تويوتا هايلوكس - بيك اب | C13: 88646 و بغداد | D13: 2012 | E13: شركة القبس للمقاولات | F13: =DATE(2028,6,5) -> 46909 | G13: =IF(F13<NOW(),"تنبية","") | H13: المقر | I13: مروان مصطفى | K13: ='تويوتا بكب 88646'!F36 -> 2036000 | L13: ='تويوتا بكب 88646'!G36 -> 150
A14: =A13+1 -> 10 | B14: تويوتا هايلوكس - بيك اب | C14: 71711 أ بغداد | D14: 2013 | E14: شركة سمو بغداد | F14: =DATE(2027,11,2) -> 46693 | G14: =IF(F14<NOW(),"تنبية","") | H14: جلولاء | I14: حسام | K14: ='تويوتا بكب 71711'!F34 -> 795000 | L14: ='تويوتا بكب 71711'!G34 -> 0
A15: =A14+1 -> 11 | B15: تويوتا هايلوكس - بيك اب | C15: 9364 أ بصرة | D15: 2011 | E15: شركة القبس للمقاولات | F15: =DATE(2029,10,6) -> 47397 | G15: =IF(F15<NOW(),"تنبية","") | H15: المقر | K15: ='تويوتا بكب 9364'!F37 -> 7574750 | L15: ='تويوتا بكب 9364'!G37 -> 0
A16: =A15+1 -> 12 | B16: تويوتا هايلوكس - بيك اب | C16: 11 H 38020 | D16: 2008 | E16: شركة القبس للمقاولات | F16: =DATE(2027,4,19) -> 46496 | G16: =IF(F16<NOW(),"تنبية","") | H16: خان ضاري | K16: ='تويوتا بكب 38020'!F36 -> 3316000 | L16: ='تويوتا بكب 38020'!G36 -> 0
A17: =A16+1 -> 13 | B17: تويوتا هايلوكس 4 سلندر - بيك اب | C17: 11 H 68461 | D17: 2025 | E17: شركة القبس للمقاولات | F17: =DATE(2029,12,12) -> 47464 | G17: =IF(F17<NOW(),"تنبية","") | H17: المقر | I17: ياسر طالب | K17: ='H 68461 تويوتا بكب'!F100 -> 0 | L17: ='H 68461 تويوتا بكب'!G100 -> 0
A18: =A17+1 -> 14 | B18: تويوتا هايلوكس 6 سلندر - بيك اب | C18: 11 H 83043 | D18: 2025 | E18: خالد علي | F18: =DATE(2029,12,21) -> 47473 | G18: =IF(F18<NOW(),"تنبية","") | H18: المقر | I18: علي غازي | K18: ='H 83043 تويوتا بكب '!F110 -> 1618320 | L18: ='H 83043 تويوتا بكب '!G110 -> 220
A19: =A18+1 -> 15 | B19: تويوتا هايلوكس - بيك اب | C19: 11 F 46601 | D19: 2025 | E19: شركة القبس للمقاولات | F19: 47717 | G19: =IF(F19<NOW(),"تنبية","") | H19: جلولاء | I19: مهندس سعد | K19: ='2025 تويوتا بكب (2)'!F100 -> 0 | L19: ='2025 تويوتا بكب (2)'!G100 -> 0
A20: =A19+1 -> 16 | B20: تويوتا هايلوكس - بيك اب | C20: 11 F 46605 | D20: 2025 | E20: شركة القبس للمقاولات | F20: 47718 | G20: =IF(F20<NOW(),"تنبية","") | H20: المقر | I20: م. عبد المهيمن | K20: ='2025 تويوتا بكب (3)'!F100 -> 0 | L20: ='2025 تويوتا بكب (3)'!G100 -> 0
A21: =A20+1 -> 17 | B21: تويوتا هايلوكس - بيك اب | C21: 11 F 46602 | D21: 2025 | E21: شركة القبس للمقاولات | F21: 47719 | G21: =IF(F21<NOW(),"تنبية","") | H21: الدورة | K21: ='2025 تويوتا بكب (4) '!F100 -> 0 | L21: ='2025 تويوتا بكب (4) '!G100 -> 0
A22: =A21+1 -> 18 | B22: تويوتا هايلوكس - بيك اب | C22: 49923 أ بغداد | D22: 2009 | E22: شركة القبس للمقاولات | F22: =DATE(2027,3,6) -> 46452 | G22: =IF(F22<NOW(),"تنبية","") | H22: خان ضاري | I22: م منذر | K22: ='تويوتا بكب 49923'!F39 -> 3591000 | L22: ='تويوتا بكب 49923'!G39 -> 0
A23: البيكبات /كيا
A24: =A22+1 -> 19 | B24: كيا دبل قمارة | C24: 11 H 87740 | D24: 2019 | E24: شركة القبس للمقاولات | F24: =DATE(2029,6,11) -> 47280 | G24: =IF(F24<NOW(),"تنبية","") | H24: خان ضاري | K24: ='كيا 87740'!F24 -> 4419000 | L24: ='كيا 87740'!G24 -> 0
A25: =A24+1 -> 20 | B25: كيا قمارة | C25: 84103 هـ بغداد | D25: 2019 | E25: شركة القبس للمقاولات | F25: =DATE(2029,6,9) -> 47278 | G25: =IF(F25<NOW(),"تنبية","") | H25: خان ضاري | K25: ='كيا 84103'!F67 -> 5445500 | L25: ='كيا 84103'!G67 -> 0
A26: =A25+1 -> 21 | B26: كيا دبل قمارة | C26: 87065 ك بغداد | D26: 2013 | E26: شركة القبس للمقاولات | F26: =DATE(2028,10,28) -> 47054 | G26: =IF(F26<NOW(),"تنبية","") | H26: خان ضاري | K26: ='كيا 87065'!F79 -> 8010000 | L26: ='كيا 87065'!G79 -> 0
A27: =A26+1 -> 22 | B27: كيا دبل قمارة | C27: 68783 أ بغداد | D27: 2013 | E27: شركة سمو بغداد | F27: =DATE(2027,10,29) -> 46689 | G27: =IF(F27<NOW(),"تنبية","") | H27: جلولاء | K27: ='كيا 68783 '!F49 -> 2082000 | L27: ='كيا 68783 '!G49 -> 780
A28: =A27+1 -> 23 | B28: كيا قمارة | C28: 80540 و بغداد | D28: 2012 | E28: شركة القبس للمقاولات | F28: =DATE(2027,6,11) -> 46549 | G28: =IF(F28<NOW(),"تنبية","") | H28: جلولاء | K28: ='كيا 80540'!F48 -> 5632000 | L28: ='كيا 80540'!G48 -> 0
A29: =A28+1 -> 24 | B29: كيا دبل قمارة | C29: 4462 أ بغداد | D29: 2009 | E29: شركة القبس للمقاولات | F29: =DATE(2028,3,6) -> 46818 | G29: =IF(F29<NOW(),"تنبية","") | H29: خان ضاري | K29: ='كيا 4462'!F115 -> 5207000 | L29: ='كيا 4462'!G115 -> 0
A30: =A29+1 -> 25 | B30: كيا دبل قمارة | C30: 41711 ط بغداد | D30: 2019 | E30: شركة القبس للمقاولات | F30: =DATE(2029,6,9) -> 47278 | G30: =IF(F30<NOW(),"تنبية","") | H30: خان ضاري | K30: ='كيا 41711'!F47 -> 3232500 | L30: ='كيا 41711'!G47 -> 0
A31: =A30+1 -> 26 | B31: كيا دبل قمارة | C31: 46696 هـ بغداد | D31: 2013 | E31: شركة القبس للمقاولات | F31: =DATE(2028,8,14) -> 46979 | G31: =IF(F31<NOW(),"تنبية","") | H31: جلولاء | K31: ='كيا 46696'!F41 -> 4711000 | L31: ='كيا 46696'!G41 -> 187
A32: =A31+1 -> 27 | B32: كيا دبل قمارة | C32: 11 M 99237 | D32: 2024 | E32: شركة القبس للمقاولات | F32: =DATE(2029,12,25) -> 47477 | G32: =IF(F32<NOW(),"تنبية","") | H32: خان ضاري | K32: ='كيا 99237 '!F16 -> 70000 | L32: ='كيا 99237 '!G16 -> 0
A33: =A32+1 -> 28 | B33: مسيوبيشي كنتر بيك اب | C33: 94707 هـ بغداد | D33: 2020 | E33: شركة القبس للمقاولات | F33: 47792 | G33: =IF(F33<NOW(),"تنبية","") | H33: أبو غريب | K33: ='كنتر بيك اب 94707'!F33 -> 635000 | L33: ='كنتر بيك اب 94707'!G33 -> 340
A34: الخباطات
A35: =A33+1 -> 29 | B35: خباطة كونكريت -سكانيا | C35: 11 H 50955 | D35: 2004 | E35: شركة القبس للمقاولات | F35: 47332 | G35: =IF(F35<NOW(),"تنبية","") | H35: خان ضاري | K35: ='خباطة 50955'!F34 -> 6800000 | L35: ='خباطة 50955'!G34 -> 700
A36: =A35+1 -> 30 | B36: خباطة كونكريت - مان | C36: 94900 ط بغداد | D36: 2007 | E36: شركة القبس للمقاولات | F36: 45247 | G36: =IF(F36<NOW(),"تنبية","") -> تنبية | H36: خان ضاري | K36: ='خباطة 94900'!F56 -> 9772000 | L36: ='خباطة 94900'!G56 -> 350
A37: =A36+1 -> 31 | B37: خباطة كونكريت - مان | C37: 53389 ك بغداد | D37: 2006 | E37: شركة القبس للمقاولات | F37: 47078 | G37: =IF(F37<NOW(),"تنبية","") | H37: خان ضاري | K37: ='خباطة 53389'!F35 -> 4627000 | L37: ='خباطة 53389'!G35 -> 750
A38: =A37+1 -> 32 | B38: خباطة كونكريت - مان | C38: 29500 ك بغداد | D38: 2007 | E38: شركة القبس للمقاولات | F38: 47078 | G38: =IF(F38<NOW(),"تنبية","") | H38: جلولاء | K38: ='خباطة 29501'!F32 -> 3444750 | L38: ='خباطة 29501'!G32 -> 250
A39: =A38+1 -> 33 | B39: خباطة كونكريت -سكانيا | C39: 60035 ن بغداد | D39: 2006 | E39: شركة القبس للمقاولات | F39: 47072 | G39: =IF(F39<NOW(),"تنبية","") | H39: أبو غريب | K39: ='خباطة 60036'!F28 -> 10599000 | L39: ='خباطة 60036'!G28 -> 0
A40: =A39+1 -> 34 | B40: خباطة كونريت - مارسيدس | C40: 10976 سليمانية | D40: 2017 | E40: خالد علي | F40: 46760 | G40: =IF(F40<NOW(),"تنبية","") | H40: الدورة | K40: ='خباطة 10976'!F31 -> 2048500 | L40: ='خباطة 10976'!G31 -> 0
A41: =A40+1 -> 35 | B41: خباطة كونريت - مارسيدس | C41: C 24000 | D41: 2019 | E41: خالد علي | F41: 47508 | G41: =IF(F41<NOW(),"تنبية","") | H41: جلولاء | K41: =' C 24000- خباطة'!F98 -> 1730000 | L41: =' C 24000- خباطة'!G98 -> 250
...

Sheet C 22730
A1: صيانة الاليات
A2: 1 | B2: شفل بوب كات | E2: الموديل | F2: 2024 | H2: الموقع: | I2: المقر | K2: رجوع الى جدول الاليات
B3: رقمها : | C3: C 22730 | E3: المالك | F3: خالد علي صالح | H3: مسؤول الالية :
B5: الشهر | E5: العداد السابق | H5: العداد النهائي :
A6: # | B6: اسم السائق/المسؤول | C6: رقم الوصل | D6: تاريخ | E6: تفاصيل الصيانه | F6: المبلغ دينار | G6: المبلغ $ | H6: مسؤول الصيانه | I6: اضافة /هايدوليك لتر | J6: العداد
A7: 1
A8: 2
A9: 3
A10: 4
A11: 5
A12: 6
A13: 7
A14: 8
A15: 30
A16: 31
A17: 32
A18: 33
... A97: 112
B98: المجموع الكلي | F98: =SUM(F7:F97) -> 0 | G98: =SUM(G7:G97) -> 0

Sheet 366
A1: صيانة الاليات
A2: 1 | B2: شفل بوب كات | E2: الموديل | F2: 1974 | H2: الموقع: | I2: المقر | K2: رجوع الى جدول الاليات
B3: رقمها : | C3: 366 | E3: المالك | F3: شركة القبس للمقاولات | H3: مسؤول الالية :
B5: الشهر | E5: العداد السابق | H5: العداد النهائي :
A6: # | B6: اسم السائق/المسؤول | C6: رقم الوصل | D6: تاريخ | E6: تفاصيل الصيانه | F6: المبلغ دينار | G6: المبلغ $ | H6: مسؤول الصيانه | I6: اضافة /هايدوليك لتر | J6: العداد
A7: 1 | C7: 1158 | D7: 18/3/2026 | E7: تشييش راديتر+لحيم راس باتري+جوين+بنجر+كت كير كامل+طقم جك ستيرن+فلاتر+مبردة كير+لايت+رنك كبوس+كاترج+كت واشرات بم+شوته اصليه+فلاتر | F7: 1705000 | H7: علي غازي
A8: 2
A9: 3
A10: 4
A11: 5
A12: 6
A13: 7
A14: 8
A15: 30
A16: 31
A17: 32
A18: 33
A19: 34
... A97: 112
B98: المجموع الكلي | F98: =SUM(F7:F97) -> 1705000 | G98: =SUM(G7:G97) -> 0

Sheet C8365
A1: صيانة الاليات
A2: 1 | B2: شفل بوب كات | E2: الموديل | F2: 2018 | H2: الموقع: | I2: المقر | K2: رجوع الى جدول الاليات
B3: رقمها : | C3: C8365 | E3: المالك | F3: خالد علي | H3: مسؤول الالية :
B5: الشهر | E5: العداد السابق | H5: العداد النهائي :
A6: # | B6: اسم السائق/المسؤول | C6: رقم الوصل | D6: تاريخ | E6: تفاصيل الصيانه | F6: المبلغ دينار | G6: المبلغ $ | H6: مسؤول الصيانه | I6: اضافة /هايدوليك لتر | J6: العداد
A7: 1
A8: 2
A9: 3
A10: 4
A11: 5
A12: 6
A13: 7
A14: 8
A15: 30
A16: 31
A17: 32
A18: 33
... A97: 112
B98: المجموع الكلي | F98: =SUM(F7:F97) -> 0 | G98: =SUM(G7:G97) -> 0

Sheet C23987
A1: صيانة الاليات
A2: 1 | B2: JCB حجم كبير | E2: الموديل | F2: 2018 | H2: الموقع: | I2: المقر | K2: رجوع الى جدول الاليات
B3: رقمها : | C3: C23987 | E3: المالك | F3: وليد خالد | H3: مسؤول الالية :
B5: الشهر | E5: العداد السابق | H5: العداد النهائي :
A6: # | B6: اسم السائق/المسؤول | C6: رقم الوصل | D6: تاريخ | E6: تفاصيل الصيانه | F6: المبلغ دينار | G6: المبلغ $ | H6: مسؤول الصيانه | I6: اضافة /هايدوليك لتر | J6: العداد
A7: 1 | C7: 960 | D7: 46358 | E7: روبن+فلاتر+كماليات+ماسحه امامي و خلفي | F7: 317000 | H7: علي غازي
A8: 2 | C8: 1093 | D8: 46086 | E8: دبة دهن + فلتر دهن + فلتر كاز | F8: 355000 | H8: علي غازي
A9: 3 | C9: 1158 | D9: 18/3/2026 | E9: كهربائيات+اجور عمل | F9: 250000 | H9: علي غازي
A10: 4 | C10: 1281 | D10: 18/4/2026 | E10: هندل | F10: 505000 | H10: علي غازي
A11: 5 | C11: 1394 | D11: 46300 | E11: فلاتر عدد2 | F11: 70000 | H11: علي غازي
A12: 6 | C12: 1428 | D12: 18/5/2026 | E12: تبريد | F12: 465000 | H12: علي غازي
A13: 7
A14: 8
A15: 30
A16: 31
A17: 32
A18: 33
A19: 34
A20: 35
A21: 36
A22: 37
A23: 38
A24: 39
... A97: 112
B98: المجموع الكلي | F98: =SUM(F9:F97) -> 1290000 | G98: =SUM(G7:G97) -> 0

Sheet  C 24000- خباطة
A1: صيانة الاليات
A2: 1 | B2: خباطة كونريت - مارسيدس | E2: الموديل | F2: 2018 | H2: الموقع: | I2: المقر | K2: رجوع الى جدول الاليات
B3: رقمها : | C3: C 24000 | E3: المالك | F3: خالد علي | H3: مسؤول الالية :
B5: الشهر | E5: العداد السابق | H5: العداد النهائي :
A6: # | B6: اسم السائق/المسؤول | C6: رقم الوصل | D6: تاريخ | E6: تفاصيل الصيانه | F6: المبلغ دينار | G6: المبلغ $ | H6: مسؤول الصيانه | I6: اضافة /هايدوليك لتر | J6: العداد
A7: 1 | C7: 960 | D7: 46358 | E7: لزكات+ارضيات+شوته+تخم فلاتر+فحص حاسبه+سستم ادبلو+جلي ويلات+كهربائيات+تبديل اطارات+اجور نقل | F7: 1730000 | G7: 250 | H7: علي غازي
A8: 2
A9: 3
A10: 4
A11: 5
A12: 6
A13: 7
A14: 8
A15: 30
A16: 31
A17: 32
A18: 33
A19: 34
... A97: 112
B98: المجموع الكلي | F98: =SUM(F7:F97) -> 1730000 | G98: =SUM(G7:G97) -> 250

Sheet C 24135- خباطة 
A1: صيانة الاليات
A2: 1 | B2: خباطة كونكريت مرسيدس | E2: الموديل | F2: 2018 | H2: الموقع: | I2: المقر | K2: رجوع الى جدول الاليات
B3: رقمها : | C3: C 24135 | E3: المالك | F3: خالد علي | H3: مسؤول الالية :
B5: الشهر | E5: العداد السابق | H5: العداد النهائي :
A6: # | B6: اسم السائق/المسؤول | C6: رقم الوصل | D6: تاريخ | E6: تفاصيل الصيانه | F6: المبلغ دينار | G6: المبلغ $ | H6: مسؤول الصيانه | I6: اضافة /هايدوليك لتر | J6: العداد
A7: 1 | C7: 960 | D7: 46358 | E7: لزكات+ارضيات+شوته+تخم فلاتر+فحص حاسبه+سستم ادبلو+جلي ويلات+كهربائيات+تبديل اطارات+اجور نقل | F7: 1730000 | G7: 250 | H7: علي غازي
A8: 2
A9: 3
A10: 4
A11: 5
A12: 6
A13: 7
A14: 8
A15: 30
A16: 31
A17: 32
A18: 33
A19: 34
... A97: 112
B98: المجموع الكلي | F98: =SUM(F7:F97) -> 1730000 | G98: =SUM(G7:G97) -> 250

Sheet C 24283 - خباطة 
A1: صيانة الاليات
A2: 1 | B2: خباطة كونكريت - مرسيدس | E2: الموديل | F2: 2018 | H2: الموقع: | I2: المقر | K2: رجوع الى جدول الاليات
B3: رقمها : | C3: C 24283 | E3: المالك | F3: خالد علي | H3: مسؤول الالية :
B5: الشهر | E5: العداد السابق | H5: العداد النهائي :
A6: # | B6: اسم السائق/المسؤول | C6: رقم الوصل | D6: تاريخ | E6: تفاصيل الصيانه | F6: المبلغ دينار | G6: المبلغ $ | H6: مسؤول الصيانه | I6: اضافة /هايدوليك لتر | J6: العداد
A7: 1 | C7: 960 | D7: 46358 | E7: لزكات+ارضيات+شوته+تخم فلاتر+فحص حاسبه+سستم ادبلو+جلي ويلات+كهربائيات+تبديل اطارات+اجور نقل | F7: 1730000 | G7: 250 | H7: علي غازي
A8: 2
A9: 3
A10: 4
A11: 5
A12: 6
A13: 7
A14: 8
A15: 30
A16: 31
A17: 32
A18: 33
A19: 34
... A97: 112
B98: المجموع الكلي | F98: =SUM(F7:F97) -> 1730000 | G98: =SUM(G7:G97) -> 250

Sheet توسان 88707
A1: صيانة الاليات
A2: 1 | B2: هونداي توسان ستيشن | E2: الموديل | F2: 2018 | H2: الموقع: | I2: المقر | K2: رجوع الى جدول الاليات
B3: رقمها : | C3: 88707 هـ بغداد | E3: المالك | F3: شركة القبس | H3: مسؤول الالية : | I3: خالد ياسين
B5: الشهر | C5: 2025/31/07 | E5: العداد السابق | F5: =J9 -> 100000 | H5: العداد النهائي : | I5: =MAX(J7:J120) -> 126000
A6: # | B6: اسم السائق/المسؤول | C6: رقم الوصل | D6: تاريخ | E6: تفاصيل الصيانه | F6: المبلغ دينار | G6: المبلغ $ | H6: مسؤول الصيانه | I6: اضافة /هايدوليك لتر | J6: العداد
A7: 1 | B7: هيثم قاسم | C7: 5601 | D7: 45117 | E7: صدر+نوزلات+فيتبم+بلكات+مشط ستيرن | F7: 1230000 | H7: هيثم قاسم
A8: 2 | B8: هيثم قاسم | C8: 6777 | D8: 20/7/2024 | E8: شراء بطاريه+صيانة كير مع تبديل دهن | F8: 260000 | H8: هيثم قاسم
A9: 3 | B9: هيثم قاسم | C9: 8097 | D9: 45742 | E9: دهن+فلتر | F9: 50000 | H9: عمر رمضان | J9: 100000
A10: 4 | B10: خالد ياسين | C10: 8146 | D10: 45759 | E10: لايت + غسل | F10: 20000 | H10: خالد ياسين
A11: 5 | B11: خالد ياسين | C11: 8872 | D11: 45801 | E11: دوشمة توسان | F11: 160000 | H11: هيثم قاسم
A12: 6 | B12: خالد ياسين | C12: 9176 | D12: 45845 | E12: دهن+فلتر | F12: 44500 | H12: عمر رمضان | J12: 104500
A13: 7 | B13: خالد ياسين | C13: 223 | D13: 45668 | E13: دهن+فلتر+ماء | F13: 49500 | H13: خالد ياسين | J13: 112000
A14: 8 | B14: خالد ياسين | C14: 700 | D14: 46204 | E14: دهن+فلتر | F14: 44500 | H14: خالد ياسين | J14: 116869
A15: 30 | B15: خالد ياسين | C15: 1107 | D15: 46268 | E15: دهن+فلتر+فلتر شوته | F15: 59000 | H15: خالد ياسين | J15: 121052
A16: 31 | B16: خالد ياسين | C16: 1213 | D16: 46116 | E16: صيانه+درع+دبة ماء | F16: 225000 | H16: خالد ياسين
A17: 32 | B17: خالد ياسين | C17: 1429 | D17: 19/5/2026 | E17: دهن+فلتر | F17: 60000 | H17: خالد ياسين | J17: 126000
A18: 33
A19: 34
A20: 35
A21: 36
A22: 37
A23: 38
A24: 39
A25: 40
A26: 41
A27: 42
A28: 43
A29: 44
... A97: 112
B98: المجموع الكلي | F98: =SUM(F7:F96) -> 2202500 | G98: =SUM(G7:G96) -> 0

Sheet  11 A 71993 تويوتا بيك اب
A1: صيانة الاليات
A2: 2 | B2: بيك اب | E2: الموديل | F2: 2019 | H2: الموقع: | I2: المقر | K2: رجوع الى جدول الاليات
B3: رقمها : | C3: 11 A 71993 | E3: المالك | F3: شركة القبس | H3: مسؤول الالية : | I3: أبو مروان
B5: الشهر | C5: 2025/31/07 | E5: العداد السابق | H5: العداد النهائي : | I5: =MAX(J7:J141) -> 81700
A6: # | B6: اسم السائق / المسؤول | C6: رقم الوصل | D6: تاريخ | E6: تفاصيل الصيانه | F6: المبلغ دينار | G6: المبلغ $ | H6: مسؤول الصيانه | I6: اضافة /هايدوليك لتر | J6: العداد
A7: 1 | B7: ابومروان | C7: 5324 | D7: 44993 | E7: دهن + فلتر | F7: 47000 | H7: ابومروان
A8: 2 | B8: ابومروان | C8: 5492 | D8: 16/9/2023 | E8: بطاريه | F8: 75000 | H8: احمد عبدالرزاق
A9: 3 | B9: ابومروان | C9: 5715 | D9: 44937 | E9: صيانه + بنزين | F9: 128000 | H9: ابومروان
A10: 4 | B10: ابومروان | C10: 5918 | D10: 19/12/2023 | E10: دهن + فلتر | F10: 50000 | H10: شاكر محمود
A11: 5 | B11: ابومروان | C11: 6215 | D11: 19/2/2024 | E11: اطارات | F11: 290000 | H11: شاكر محمود
A12: 6 | B12: ابومروان | C12: 6456 | D12: 45327 | E12: دهن + فلتر | F12: 60000 | H12: ابومروان
A13: 7 | B13: ابومروان | C13: 6793 | D13: 24/7/2024 | E13: دسكات+دهن + فلتر | F13: 168000 | H13: ابومروان
A14: 8 | B14: ابومروان | C14: 7092 | D14: 45565 | E14: بدنه+كوشه+لايت/تصليح دعمه | F14: 420000 | H14: م.مروان
A15: 9 | B15: ابومروان | D15: 45580 | E15: مواد تصليح ضربة الدعاميه | F15: 285000 | H15: ابومروان
A16: 10 | B16: ابومروان | C16: 7286 | D16: 45600 | E16: ادامه/تبديل فلتر+واشر+دهن كير+فلاتر بنزين+شوته+دهن+دهن محرك+دهن اكسلات+فلاش محرك+تشحيم كاردن | F16: 450000 | H16: ابومروان
A17: 11 | B17: ابومروان | C17: 7698 | D17: 45671 | E17: صيانة زيوت متنوعه | F17: 120000 | H17: م.مروان
A18: 12 | B18: ابومروان | C18: 8929 | D18: 45808 | E18: دهن+فلتر | F18: 75000 | H18: ابومروان
A19: 13 | B19: ابومروان | C19: 9368 | D19: 45865 | E19: بطاريه | F19: 85000 | H19: عمر رمضان
A20: 14 | C20: 187 | D20: 45958 | E20: دهن+فلتر | F20: 75000 | H20: عبدالوهاب بدر | J20: 81700
A21: 15 | C21: 1395 | D21: 46300 | E21: تبديل دهن محرك+كير+فلاتر | F21: 310000 | H21: عبدالوهاب بدر
A22: 16
A23: 17
A24: 18
A25: 19
A26: 20
A27: 21
A28: 22
A29: 23
A30: 24
A31: 25
A32: 26
A33: 27
... A50: 44
B51: المجموع الكلي | F51: =SUM(F7:F50) -> 2638000 | G51: =SUM(G7:G50) -> 0

Sheet 11 W 8011 تاهو
A1: صيانة الاليات
A2: 3 | B2: تاهو شوفرليت | E2: الموديل | F2: 2021 | H2: الموقع: | I2: المقر | K2: رجوع الى جدول الاليات
B3: رقمها : | C3: 11 W 8011 | E3: المالك | F3: خالد علي | H3: مسؤول الالية :
B5: الشهر | C5: 2025/31/07 | E5: العداد السابق | H5: العداد النهائي : | I5: =MAX(J7:J141) -> 0
A6: # | B6: اسم السائق / المسؤول | C6: رقم الوصل | D6: تاريخ | E6: تفاصيل الصيانه | F6: المبلغ دينار | G6: المبلغ $ | H6: مسؤول الصيانه | I6: اضافة /هايدوليك لتر | J6: ملاحظات
A7: 25 | B7: المقر | C7: 4342 | D7: 17/1/2023 | E7: غسل | F7: 20000
A8: 28 | B8: المقر | C8: 4594 | D8: 44960 | E8: دهن+غسل+بنزين | F8: 50000 | G8: 150 | H8: احمد عبدالرزاق
A9: 29 | B9: المقر | C9: 4697 | D9: 22/3/2023 | E9: غرامه مروريه | F9: 50000 | H9: احمد عبدالرزاق
A10: 31 | B10: المقر | C10: 4768 | D10: 45081 | E10: اطارات+بنزين | F10: 95000 | G10: 640 | H10: احمد عبدالرزاق
A11: 33 | B11: المقر | C11: 5025 | D11: 44991 | E11: درع جام امامي | G11: 200 | H11: احمد عبدالرزاق
A12: 34 | B12: المقر | C12: 5052 | D12: 45083 | E12: هورن | F12: 80000 | H12: احمد عبدالرزاق
A13: 41 | B13: المقر | C13: 5752 | D13: 45149 | E13: دسكات | G13: 450 | H13: احمد عبدالرزاق
A14: 42 | B14: المقر | C14: 5768 | D14: 13/11/2023 | E14: اجور عمل دسكات + بنزين | F14: 75000 | H14: احمد عبدالرزاق
A15: 46 | B15: المقر | C15: 6442 | D15: 27/4/2024 | E15: درع جام امامي | F15: 350000 | H15: احمد عبدالرزاق
A16: 47 | B16: المقر | C16: 6474 | D16: 45448 | E16: دهن + فلتر | F16: 147500 | H16: احمد عبدالرزاق
A17: 48 | B17: المقر | C17: 6886 | D17: 45573 | E17: تبديل دهن+فلتر +فلترشوته+غسل+شراء بخاخ للاملاح القماره+نصب كامره اماميه | F17: 206000 | H17: احمد عبدالرزاق
A18: 49 | B18: المقر | D18: 45566 | E18: بطارية ريمونت+فلتر شوته | F18: 30000 | H18: احمد عبدالرزاق
A19: 50 | B19: المقر | C19: 7406 | D19: 45627 | E19: كامرة تسجيل داش كام | F19: 330000 | H19: م. وليد القيسي
A20: 51 | B20: المقر | C20: 7412 | D20: 45628 | E20: اجور كهربائي عن نصب كامره+غسل | F20: 45000 | H20: احمد عبدالرزاق
A21: 52 | B21: المقر | C21: 7568 | D21: 45645 | E21: تصليح جامه اماميه | F21: 15000 | H21: احمد عبدالرزاق
A22: 53 | B22: المقر | C22: 8157 | D22: 45761 | E22: تبديل ماطور ماسحات+برمجه | F22: 200000 | H22: احمد عبدالرزاق
A23: 54 | B23: المقر | C23: 8810 | D23: 45791 | E23: دهن+فلاتر تبريد و شوته+فحص كومبيوتر | F23: 220000 | H23: احمد عبدالرزاق
A24: 55 | B24: المقر | C24: 9438 | D24: 45874 | E24: تبديل حساس اي بي اس | F24: 140000 | H24: احمد عبدالرزاق
A25: 56 | B25: المقر | C25: 564 | D25: 46011 | E25: تصليح اكسل+تبديل فلاوين+بطاريه+اذانات محرك+بلنص+غسل | F25: 3635000 | H25: احمد عبدالرزاق
A26: 57 | B26: المقر | C26: 1392 | D26: 46270 | E26: تبديل دهن+فلاتر+ماء راديتر+تنظيف جويتر+بطاريه | F26: 860000 | H26: عمر رمضان
A27: 58
A28: 59
A29: 60
A30: 61
A31: 62
A32: 63
A33: 64
A34: 65
B35: المجموع الكلي | F35: =SUM(F7:F34) -> 6548500 | G35: =SUM(G7:G34) -> 1440
A36: =A36:K54 -> 0

Sheet برادو 2009
A1: صيانة الاليات
A2: 5 | B2: تويوتا برادو ستيشن | E2: الموديل | F2: 2009 | H2: الموقع: | I2: المقر | K2: رجوع الى جدول الاليات
B3: رقمها : | C3: 11734 د بغداد | E3: المالك | F3: شركة القبس | H3: مسؤول الالية :
B5: الشهر | C5: 2025/31/07 | E5: العداد السابق | H5: العداد النهائي : | I5: =MAX(J7:J141) -> 178000
A6: # | B6: اسم السائق / المسؤول | C6: رقم الوصل | D6: تاريخ | E6: تفاصيل الصيانه | F6: المبلغ دينار | G6: المبلغ $ | H6: مسؤول الصيانه | I6: اضافة /هايدوليك لتر | J6: العداد
A7: 25 | B7: المقر | C7: 4342 | D7: 17/1/2023 | E7: غسل | F7: 25000 | H7: الموصل
A8: 29 | B8: المقر | C8: قيد 134 | D8: 45088 | E8: اطارات + غسل + بنزين | F8: 881000 | H8: الموصل
A9: 30 | B9: المقر | C9: قيد 15 | D9: 45414 | E9: صيانه | F9: 250000 | H9: الموصل
A10: 46 | B10: المقر | C10: 6442 | D10: 27/4/2024 | E10: لايت امامي | F10: 50000 | H10: احمد عبدالرزاق
A11: 32 | B11: المقر | C11: 6421 | D11: 29/4/2024 | E11: تبديل مصابيح خلفيه+فلتر تبريد | F11: 50000 | H11: احمد عبدالرزاق
A12: 33 | B12: المقر | C12: 6528 | D12: 22/5/2024 | E12: شمعات+هورن+غسل | F12: 175000 | H12: احمد عبدالرزاق
A13: 34 | B13: المقر | C13: 6907 | D13: 14/8/2024 | E13: جامه خلفيه | F13: 90000 | H13: احمد عبدالرزاق
A14: 35 | B14: المقر | C14: 7043 | D14: 45553 | E14: تبديل مشط ستيرن | F14: 230000 | H14: شاكر محمود
A15: 36 | B15: المقر | D15: 45574 | E15: دهن+فلتر+فلتر شوته+فلتر تبريد | F15: 85000 | H15: احمد عبدالرزاق
A16: 37 | B16: المقر | C16: 8122 | D16: 45754 | E16: دهن+فلتر | F16: 52000 | H16: عمر رمضان
A17: 38 | B17: المقر | C17: 8135 | D17: 45756 | E17: تصليح صدر + تبديل صرة دهن | F17: 150000 | H17: احمد عبدالرزاق
A18: 39 | B18: المقر | C18: 8794 | D18: 45789 | E18: تصليح دعاميه+قواعد | F18: 65000 | H18: عمر رمضان
A19: 40 | B19: المقر | C19: 8857 | D19: 45798 | E19: دهن+فلاتر شوته و دهن+عمل باج | F19: 135000 | H19: عمر رمضان
A20: 41 | B20: المقر | C20: 9357 | D20: 45864 | E20: دهن+فلتر+فلتر تبريد | F20: 57000 | H20: عمر رمضان
A21: 42 | B21: المقر | C21: 9382 | D21: 45866 | E21: بطاريه | F21: 106000 | H21: عمر رمضان
A22: 43 | B22: المقر | C22: 9740 | D22: 45913 | E22: دسكات امامي+خلفي+عمل | F22: 237250 | H22: عبدالوهاب
A23: 44 | B23: المقر | C23: 9889 | D23: 45928 | E23: لاستيك دبل+فلنجات امامي+دهن هيدروليك+برغي مشط+درايف شفت ميزانيه+اجور عمل | F23: 2100000 | H23: عبدالوهاب
A24: 45 | C24: 222 | D24: 45668 | E24: دهن+فلتر | F24: 75000 | H24: عمر رمضان | J24: 178000
A25: 46 | C25: 770 | D25: 13/1/2026 | E25: تصليح جامه | F25: 35000 | H25: عمر رمضان
A26: 47 | C26: 1405 | D26: 14/5/2026 | E26: غاز تبريد+فلتر | F26: 40000 | H26: عمر رمضان
A27: 48
A28: 49
A29: 50
A30: 51
A31: 52
A32: 53
A33: 54
A34: 55
A35: 56
A36: 57
A37: 58
A38: 59
... A42: 63
B43: المجموع الكلي | F43: =SUM(F7:F42) -> 4888250 | G43: =SUM(G7:G42) -> 0

Sheet 2022 البرادو 
A1: صيانة الاليات
A2: 4 | B2: تويوتا برادو | E2: الموديل | F2: 2022 | H2: الموقع: | I2: المقر | K2: رجوع الى جدول الاليات
B3: رقمها : | C3: 52164 ن بغداد | E3: المالك | F3: تركي القيسي | H3: مسؤول الالية :
B5: الشهر | C5: 2025/31/07 | E5: العداد السابق | F5: =J26 -> 28000 | H5: العداد النهائي : | I5: =MAX(J7:J141) -> 34000
A6: # | B6: اسم السائق/المسؤل | C6: رقم الوصل | D6: تاريخ | E6: تفاصيل الصيانه | F6: المبلغ دينار | G6: المبلغ $ | H6: مسؤول الصيانه | I6: اضافة /هايدوليك لتر | J6: العداد
A7: 1 | B7: المقر | C7: 4707 | D7: 23/3/2023 | E7: غرامه+غسل+بنزين | F7: 100000 | H7: احمد عبدالرزاق
A8: 2 | B8: المقر | C8: 4722 | D8: 26/3/2023 | E8: مصاريف صيانه | F8: 1408000 | H8: احمد عبدالرزاق
A9: 3 | B9: المقر | C9: 5307 | D9: 30/7/2023 | E9: صيانه+دهن وفلتر+بنزين | F9: 190000 | H9: هيثم قاسم
A10: 4 | B10: المقر | C10: 5674 | D10: 24/10/2023 | E10: بنزين | F10: 50000 | H10: احمد عبدالرزاق
A11: 5 | B11: المقر | C11: 5736 | D11: 45027 | E11: صيانه + بنزين | F11: 60000 | H11: احمد عبدالرزاق
A12: 6 | B12: المقر | C12: 5741 | D12: 45057 | E12: صيانه + بنزين | F12: 75000 | H12: احمد عبدالرزاق
A13: 7 | B13: المقر | C13: 5771 | D13: 15/11/2023 | E13: بنزين | F13: 36000 | H13: عبدالمهيمن
A14: 8 | B14: المقر | C14: 5829 | D14: 28/11/2023 | E14: بنزين | F14: 66000 | H14: احمد عبدالرزاق
A15: 9 | B15: المقر | C15: 5895 | D15: 45272 | E15: بنزين | F15: 65000 | H15: احمد عبدالرزاق
A16: 10 | B16: المقر | C16: 5933 | D16: 23/12/2023 | E16: بنزين | F16: 60000 | H16: احمد عبدالرزاق
A17: 11 | B17: المقر | C17: 6001 | D17: 45323 | E17: غسل + بنزين | F17: 68000 | H17: عبدالمهيمن
A18: 12 | B18: المقر | C18: 6116 | D18: 27/1/2024 | E18: غرامه | F18: 25000 | H18: احمد عبدالرزاق
A19: 13 | B19: المقر | C19: 6119 | D19: 28/1/2024 | E19: بنزين | F19: 75000 | H19: هيثم قاسم
A20: 14 | B20: المقر | C20: 6126 | D20: 29/1/2024 | E20: غرامه | F20: 50000 | H20: شاكر محمود
A21: 15 | B21: المقر | C21: 6152 | D21: 31/1/2024 | E21: بنزين | F21: 50000 | H21: احمد عبدالرزاق
A22: 16 | B22: المقر | C22: 6194 | D22: 45567 | E22: بنزين | F22: 60000 | H22: احمد عبدالرزاق
A23: 17 | B23: المقر | C23: 6331 | D23: 25/3/2024 | E23: بنزين | F23: 74000 | H23: خالد ياسين
A24: 18 | B24: المقر | C24: 6817 | D24: 28/7/2024 | E24: تصليح جامه | F24: 10000 | H24: احمد عبدالرزاق
A25: 19 | B25: المقر | C25: 7262 | D25: 45598 | E25: غسل | F25: 10000 | H25: عبدالمهيمن
A26: 20 | B26: المقر | C26: 7640 | D26: 45657 | E26: دهن+فلتر | F26: 70000 | H26: خالد ياسين | J26: 28000
A27: 21 | B27: المقر | C27: 1087 | D27: 46115 | E27: دهن+فلاتر دهن وتبريد وشوته+ماء راديتر | F27: 125000 | H27: عمر رمضان | J27: 34000
A28: 22 | B28: المقر
A29: 23
A30: 24
A31: 25
A32: 26
A33: 27
A34: 28
A35: 29
A36: 30
A37: 31
A38: 32
A39: 33
A40: 34
... A53: 47
...

Sheet جيب شيروكي 
A1: صيانة الاليات
A2: 6 | B2: جيب جراند شيروكي | E2: الموديل | F2: 2024 | H2: الموقع: | I2: المقر | K2: رجوع الى جدول الاليات
B3: رقمها : | C3: 11 L 41113 | E3: المالك | F3: تركي القيسي | H3: مسؤول الالية :
B5: الشهر | C5: 2025/31/07 | E5: العداد السابق | F5: =J7 -> 2750 | H5: العداد النهائي : | I5: =MAX(J7:J141) -> 12200
A6: # | B6: اسم السائق / المسؤول | C6: رقم الوصل | D6: تاريخ | E6: تفاصيل الصيانه | F6: المبلغ دينار | G6: المبلغ $ | H6: مسؤول الصيانه | I6: اضافة /هايدوليك لتر | J6: العداد
A7: 1 | B7: المقر | C7: 7289 | D7: 45601 | E7: تغليف السياره بالكامل + تكحيل | F7: 100000 | G7: 1700 | H7: عبدالمهيمن | J7: 2750
A8: 3 | B8: المقر | C8: 7291 | D8: 45601 | E8: كامرة تسجيل طريق+رام | F8: 245000 | H8: عبدالمهيمن
A9: 4 | B9: المقر | C9: 7342 | D9: 45615 | E9: ارضيات | F9: 65000 | H9: عبدالمهيمن
A10: 5 | B10: المقر | C10: 8820 | D10: 45795 | E10: بطاريه | F10: 289000 | H10: هيثم قاسم
A11: 6 | C11: 17 | D11: 45663 | E11: دهن+فلاتر | F11: 172500 | H11: عمر رمضان | J11: 12200
A12: 7 | C12: 968 | D12: 14/2/2026 | E12: دهن+فلاتر | F12: 140000 | H12: عمر رمضان
A13: 6 | C13: 1401 | D13: 46361 | E13: دهن+فلاتر | F13: 114500 | H13: عمر رمضان
A14: 9
A15: 10
A16: 11
A17: 12
A18: 13
A19: 14
A20: 15
A21: 16
A22: 17
A23: 18
A24: 19
A25: 20
... A35: 30
B36: المجموع الكلي | F36: =SUM(F7:F35) -> 1126000 | G36: =SUM(G7:G35) -> 1700

Sheet راف فور
A1: صيانة الاليات
A2: 7 | B2: تويوتا راف فور | E2: الموديل | F2: 2024 | H2: الموقع: | I2: المقر | K2: رجوع الى جدول الاليات
B3: رقمها : | C3: 11 Q 51965 | E3: المالك | F3: القبس | H3: مسؤول الالية : | I3: هيثم قاسم
B5: الشهر | C5: 2025/31/07 | E5: العداد السابق | F5: =J7 -> 4000 | H5: العداد النهائي : | I5: =MAX(J7:J141) -> 20000
A6: # | B6: اسم السائق / المسؤول | C6: رقم الوصل | D6: تاريخ | E6: تفاصيل الصيانه | F6: المبلغ دينار | G6: المبلغ $ | H6: مسؤول الصيانه | I6: اضافة هايدوليك / لتر | J6: العداد
A7: 1 | B7: هيثم قاسم | C7: 7860 | D7: 45708 | E7: دهن+فلتر | F7: 37500 | H7: عمر رمضان | J7: 4000
A8: 3 | B8: هيثم قاسم | C8: 9197 | D8: 45847 | E8: غسل+دهن+فلتر | F8: 69000 | H8: عمر رمضان | J8: 10000
A9: 4 | B9: هيثم قاسم | C9: 222 | D9: 45668 | E9: دهن+فلتر | F9: 54000 | H9: عمر رمضان | J9: 15000
A10: 5 | B10: هيثم قاسم | C10: 1111 | D10: 46298 | E10: تصليح جامه اماميه+دهن وفلتر+تبديل شاشه رئيسيه | F10: 507000 | H10: هيثم قاسم | J10: 20000
A11: 6
A12: 7
A13: 6
A14: 9
A15: 10
A16: 11
A17: 12
A18: 13
A19: 14
A20: 15
A21: 16
A22: 17
... A35: 30
B36: المجموع الكلي | F36: =SUM(F7:F35) -> 667500 | G36: =SUM(G7:G35) -> 0

Sheet تويوتا بكب 28332
A1: صيانة الاليات
A2: 8 | B2: تويوتا هايلوكس دبل كابينة - بيك اب | E2: الموديل | F2: 2013 | H2: الموقع: | K2: رجوع الى جدول الاليات
B3: رقمها : | C3: 28332 أ بغداد | E3: المالك | F3: شركة سمو بغداد | H3: مسؤول الالية :
B5: الشهر | C5: 2025/31/07 | E5: العداد السابق | H5: العداد النهائي : | I5: =MAX(J7:J141) -> 0
A6: # | B6: اسم السائق / المسؤول | C6: رقم الوصل | D6: تاريخ | E6: تفاصيل الصيانه | F6: المبلغ دينار | G6: المبلغ $ | H6: مسؤول الصيانه | I6: اضافة /هايدوليك لتر | J6: العداد
A7: 1 | B7: محمد فوزي | C7: 4598 | D7: 45019 | E7: تصليح + بانزين | F7: 125000 | H7: محمد فوزي
A8: 2 | B8: محمد فوزي | C8: 4666 | E8: تصليح + بانزين | F8: 50000 | H8: محمد فوزي
A9: 3 | B9: محمد فوزي | C9: 5014 | D9: 44932 | E9: بانزين + تصليح بريك | F9: 307000 | H9: محمد فوزي
A10: 4 | B10: محمد فوزي | C10: 5165 | D10: 44992 | E10: تصليح + بانزين | F10: 334000 | H10: محمد فوزي
A11: 5 | B11: محمد فوزي | C11: 5365 | D11: 45268 | E11: صيانه | F11: 310000 | H11: علي غازي
A12: 6 | B12: عبدالمهيمن | C12: 5707 | D12: 31/10/2023 | E12: بانزين + غسل | F12: 37000 | H12: عبدالمهيمن
A13: 7 | B13: عبدالمهيمن | C13: 5753 | D13: 45149 | E13: تصليح + بانزين | F13: 201000 | H13: عبدالمهيمن
A14: 8 | B14: عبدالمهيمن | C14: 5771 | D14: 15/11/2023 | E14: تصليح + بانزين | F14: 570000 | H14: عبدالمهيمن
A15: 9 | B15: عبدالمهيمن | C15: 6013 | D15: 45383 | E15: تصليح | F15: 155000 | H15: شاكر محمود
A16: 10 | B16: عبدالمهيمن | C16: 6286 | D16: 45325 | E16: صيانه + بانزين | F16: 391000 | H16: عبدالمهيمن
A17: 11 | B17: عبدالمهيمن | C17: 6356 | D17: 45326 | E17: ميزانيه | F17: 30000 | H17: عبدالمهيمن
A18: 12 | B18: عبدالمهيمن | C18: 6518 | D18: 19/5/2024 | E18: تنظيف غرفة احتراق | F18: 100000 | H18: عبدالمهيمن
A19: 13 | B19: عبدالمهيمن | C19: 6565 | E19: فيت بم اصلي+قبغ تانكي+فيشه+عمل | F19: 290000 | H19: عبدالمهيمن
A20: 14 | B20: عبدالمهيمن | C20: 6938 | D20: 45526 | E20: تبديل فلتر بنزين+تبريد | F20: 60000 | H20: عبدالمهيمن
A21: 15 | B21: عبدالمهيمن | C21: 6980 | D21: 45536 | E21: اجور تبديل نوزلات | F21: 25000 | H21: عبدالمهيمن
A22: 16 | B22: عبدالمهيمن | C22: 7071 | D22: 45560 | E22: نوزلات طخم | F22: 400000 | H22: علي غازي
A23: 17 | B23: عبدالمهيمن | C23: 7285 | D23: 45596 | E23: تبديل عنبار بريك+دهن+دهن محرك و فلتر+جامه اماميه | F23: 269000 | H23: شاكر محمود
A24: 18 | B24: عبدالمهيمن | C24: 7860 | D24: 45708 | E24: دهن+فلتر | F24: 37750 | H24: عمر رمضان
A25: 19 | C25: 9738 | D25: 45913 | E25: دسكات+بولبرن امامي+بنزات+كريز+تصفير فلنجات+اجور عمل | F25: 321000 | H25: علي غازي
A26: 20 | C26: 1093 | D26: 46086 | E26: لايت+جاملغ+ماسكه+كفر مرايه | F26: 335000 | H26: علي غازي
A27: 21 | C27: 1093 | D27: 46086 | E27: اطارات | F27: 265000 | H27: علي غازي
A28: 22
A29: 23
A30: 24
A31: 25
A32: 26
A33: 27
A34: 28
A35: 29
A36: 30
A37: 31
A38: 32
A39: 33
... A54: 48
B55: المجموع الكلي | F55: =SUM(F7:F54) -> 4612750 | G55: =SUM(G7:G54) -> 0

Sheet تويوتا بكب 88646
A1: صيانة الاليات
A2: 10 | B2: تويوتا هايلوكس دبل كابينة - بيك اب | E2: الموديل | H2: الموقع: | K2: رجوع الى جدول الاليات
B3: رقمها : | C3: 88646 و بغداد | E3: المالك | F3: شركة القبس | H3: مسؤول الالية :
B5: الشهر | C5: 2025/31/07 | E5: العداد السابق | H5: العداد النهائي : | I5: =MAX(J7:J141) -> 0
A6: # | B6: اسم السائق / المسؤول | C6: رقم الوصل | D6: تاريخ | E6: تفاصيل الصيانه | F6: المبلغ دينار | G6: المبلغ $ | H6: مسؤول الصيانه | I6: اضافة /هايدوليك لتر | J6: العداد
A7: 1 | B7: م.مروان مصطفى | C7: 4608 | E7: تصليح + بنزين | F7: 435000 | H7: م.مروان مصطفى
A8: 2 | B8: م.مروان مصطفى | C8: 4776 | D8: 45142 | E8: فلاتر هواء+بنزين | F8: 30000 | H8: م.مروان مصطفى
A9: 3 | B9: م.مروان مصطفى | C9: 5334 | D9: 45054 | E9: تصليح تبريد | F9: 275000 | H9: م.مروان مصطفى
A10: 4 | B10: م.مروان مصطفى | C10: 5846 | D10: 44969 | E10: ماء راديتر | F10: 30000 | H10: م.مروان مصطفى
A11: 5 | C11: 6317 | D11: 23/3/2024 | E11: جامه امامي | F11: 75000 | H11: علي غازي
A12: 6 | C12: 7071 | D12: 45560 | E12: بطاريه | F12: 60000 | H12: علي غازي
A13: 7 | D13: 45580 | E13: دهن+فلتر25/9+14/10 | F13: 130000 | H13: علي غازي
A14: 8 | C14: 7272 | D14: 45599 | E14: دهن + فلتر | F14: 65000 | H14: علي غازي
A15: 9 | C15: 7348 | D15: 45619 | E15: تبديل اطارات امامي مع البلنص | F15: 20000 | G15: 150 | H15: علي غازي
A16: 10 | C16: 7580 | D16: 45649 | E16: دسكات امامي+زوج اطارات مع الشد وبلنص+ميزانيه | F16: 270000 | H16: علي غازي
A17: 11 | C17: 8060 | D17: 45739 | E17: دهن + فلتر + دوشمة مقاعد | F17: 172000 | H17: شاكر محمود
A18: 12 | B18: م.مروان مصطفى | C18: 8770 | D18: 45785 | E18: تبديل فيتبم+قاعده+ظفيره+غسل+اجور عمل | F18: 250000 | H18: مروان مصطفى
A19: 13 | B19: م.مروان مصطفى | C19: 8771 | D19: 45785 | E19: دهن + فلتر | F19: 65000 | H19: مروان مصطفى
A20: 14 | B20: م.مروان مصطفى | C20: 9339 | D20: 45862 | E20: دهن + فلتر | F20: 52000 | H20: عمر رمضان
A21: 15 | B21: م.مروان مصطفى | C21: 777 | D21: 13/1/2026 | E21: تصليح طوافه+عمل فتحة فيتبم | F21: 107000 | H21: مروان مصطفى
A22: 16
A23: 17
A24: 18
A25: 19
A26: 20
A27: 21
A28: 22
A29: 23
A30: 24
A31: 25
A32: 26
A33: 27
... A35: 29
B36: المجموع الكلي | F36: =SUM(F7:F35) -> 2036000 | G36: =SUM(G7:G35) -> 150

Sheet تويوتا بكب 71711
A1: صيانة الاليات
A2: 11 | B2: تويوتا هايلوكس دبل كابينة - بيك اب | E2: الموديل | F2: 2013 | H2: الموقع: | K2: رجوع الى جدول الاليات
B3: رقمها : | C3: 71711 أ بغداد | E3: المالك | F3: شركة سمو بغداد | H3: مسؤول الالية :
B5: الشهر | C5: 2025/31/07 | E5: العداد السابق | H5: العداد النهائي : | I5: =MAX(J7:J141) -> 0 | K5: الشهر :
A6: # | B6: اسم السائق / المسؤول | C6: رقم الوصل | D6: تاريخ | E6: تفاصيل الصيانه | F6: المبلغ دينار | G6: المبلغ $ | H6: مسؤول الصيانه | I6: اضافة /هايدوليك لتر | J6: العداد
A7: 4 | C7: 5488 | D7: 16/9/2023 | E7: اطارات | F7: 540000 | H7: علي غازي
A8: 5 | C8: 1281 | D8: 18/4/2026 | E8: زوج اطارات | F8: 255000 | H8: علي غازي
A9: 6
A10: 7
A11: 8
A12: 9
A13: 10
A14: 11
A15: 12
A16: 13
A17: 14
A18: 15
A19: 16
A20: 17
... A33: 30
B34: المجموع الكلي | F34: =SUM(F7:F33) -> 795000 | G34: =SUM(G7:G33) -> 0

Sheet تويوتا بكب 9364
A1: صيانة الاليات
A2: 13 | B2: تويوتا هايلوكس دبل كابينة - بيك اب | E2: الموديل | F2: 2011 | H2: الموقع: | K2: رجوع الى جدول الاليات
B3: رقمها : | C3: بصرة 9364 | E3: المالك | F3: شركة القبس | H3: مسؤول الالية :
B5: الشهر | C5: 2025/31/07 | E5: العداد السابق | H5: العداد النهائي : | I5: =MAX(J7:J141) -> 0
A6: # | B6: اسم السائق / المسؤول | C6: رقم الوصل | D6: تاريخ | E6: تفاصيل الصيانه | F6: المبلغ دينار | G6: المبلغ $ | H6: مسؤول الصيانه | I6: اضافة /هايدوليك لتر | J6: العداد
A7: 1 | C7: قيد رقم 83 | E7: صيانه + وقود | F7: 184750
A8: 2 | C8: 5922 | D8: 20/12/2023 | E8: بطاريه | F8: 85000 | H8: علي غازي
A9: 3 | C9: 6049 | D9: 13/1/2024 | E9: صيانه | F9: 3745000 | H9: علي غازي
A10: 4 | C10: 7658 | D10: 45662 | E10: تجفيت+ملحقاته+اجور عمل+عمل راديتر | F10: 1480000 | H10: علي غازي
A11: 5 | C11: 7757 | D11: 45682 | E11: بلكات+نوزل+عمل صيانه | F11: 160000 | H11: شاكر محمود
A12: 6 | C12: 9738 | D12: 45913 | E12: عنبار ويل خلفي+عنبار بريك+دهن بريك+بور ستيرن+لاستيك ولف+جبنة تايمن+جبنة بيرن+دهن وفلتر+روله وضاغطه+سيليكون+كازكيت+بلكات+ماء راديتر+فلتر شوته+فلتر بنزين+قايش محرك+رولة تبريد+واشر نوزل+دهن بور ستيرن+تخم نوزلات+حساس صالنصه+حساس في في تي كور+اجور عمل كور+اجور عمل تجفيت محرك | F12: 1735000 | H12: علي غازي
A13: 7 | C13: 101 | D13: 45948 | E13: جامه اماميه+اجور عمل+دهن+جبنه | F13: 185000 | H13: علي غازي
A14: 8
A15: 9
A16: 10
A17: 11
A18: 12
A19: 13
A20: 14
A21: 15
A22: 16
A23: 17
A24: 18
A25: 19
... A36: 30
B37: المجموع الكلي | F37: =SUM(F7:F36) -> 7574750 | G37: =SUM(G7:G36) -> 0

Sheet تويوتا بكب 38020
A1: صيانة الاليات
A2: 14 | B2: تويوتا هايلوكس دبل كابينة - بيك اب | E2: الموديل | F2: 2008 | H2: الموقع: | K2: رجوع الى جدول الاليات
B3: رقمها : | C3: 11 H 38020 | E3: المالك | F3: شركة القبس | H3: مسؤول الالية :
B5: الشهر | C5: 2025/31/07 | E5: العداد السابق | H5: العداد النهائي : | I5: =MAX(J7:J141) -> 0
A6: # | B6: اسم السائق / المسؤول | C6: رقم الوصل | D6: تاريخ | E6: تفاصيل الصيانه | F6: المبلغ دينار | G6: المبلغ $ | H6: مسؤول الصيانه | I6: اضافة /هايدوليك لتر | J6: العداد
A7: 1 | B7: علي غازي | C7: 4560 | D7: 25/2/2023 | E7: اطارات | F7: 482000 | H7: علي غازي
A8: 2 | C8: قيد 43 | D8: 44929 | E8: صيانه عامه | F8: 460000
A9: 3 | C9: 6145 | D9: 31/1/2024 | E9: تجفيت | F9: 1889000 | H9: علي غازي
A10: 4 | C10: 5922 | D10: 20/12/2023 | E10: دهن+فلتر+بنزين مرتين | F10: 104000 | H10: علي غازي
A11: 5 | C11: 7580 | D11: 45649 | E11: بطاريه | F11: 85000 | H11: علي غازي
A12: 6 | C12: 9551 | D12: 45883 | E12: دهن+فلتر | F12: 48000 | H12: شاكر محمود
A13: 7 | C13: 9762 | D13: 45914 | E13: دهن+فلتر | F13: 43000 | H13: شاكر محمود
A14: 8 | C14: 9875 | D14: 45927 | E14: تصليح منظومة وقود+تبديل جامه امامي | F14: 205000 | H14: شاكر محمود
A15: 9
A16: 10
A17: 11
A18: 12
A19: 13
A20: 14
A21: 15
A22: 16
A23: 17
A24: 18
A25: 19
A26: 20
... A35: 29
B36: المجموع الكلي | F36: =SUM(F7:F35) -> 3316000 | G36: =SUM(G7:G35) -> 0

Sheet H 68461 تويوتا بكب
A1: صيانة الاليات
A2: 15 | B2: تويوتا هايلوكس دبل كابينة - بيك اب | E2: الموديل | F2: 2025 | H2: الموقع: | K2: رجوع الى جدول الاليات
B3: رقمها : | C3: 11 H 68461 | E3: المالك | F3: القبس | H3: مسؤول الالية :
B5: الشهر | C5: 2025/31/07 | E5: العداد السابق | H5: العداد النهائي : | I5: =MAX(J7:J141) -> 0
A6: # | B6: اسم السائق / المسؤول | C6: رقم الوصل | D6: تاريخ | E6: تفاصيل الصيانه | F6: المبلغ دينار | G6: المبلغ $ | H6: مسؤول الصيانه | I6: اضافة /هايدوليك لتر | J6: العداد
A7: 1 | B7: ياسر | D7: 45939 | E7: دهن+فلتر | H7: ياسر | K7: صيانه مجانيه
A8: 3
A9: 4
A10: 5
A11: 6
A12: 7
A13: 6
A14: 9
A15: 10
A16: 11
A17: 12
A18: 13
A19: 14
... A99: 94
F100: =SUM(F7:F99) -> 0 | G100: =SUM(G7:G99) -> 0

Sheet H 83043 تويوتا بكب 
A1: صيانة الاليات
A2: 16 | B2: تويوتا هايلوكس دبل كابينة - بيك اب | E2: الموديل | F2: 2025 | H2: الموقع: | K2: رجوع الى جدول الاليات
B3: رقمها : | C3: 11 H 83043 | E3: المالك | F3: خالد علي | H3: مسؤول الالية : | I3: علي غازي
B5: الشهر | C5: 2025/31/07 | E5: العداد السابق | H5: العداد النهائي : | I5: =MAX(J7:J141) -> 0
A6: # | B6: اسم السائق / المسؤول | C6: رقم الوصل | D6: تاريخ | E6: تفاصيل الصيانه | F6: المبلغ دينار | G6: المبلغ $ | H6: مسؤول الصيانه | I6: اضافة /هايدوليك لتر | J6: العداد
A7: 1 | C7: 8981 | D7: 45813 | E7: تبديل دسكات امامي + تبديل جامه اماميه ايسر | F7: 269000 | H7: علي غازي
A8: 3 | C8: 9203 | D8: 45848 | E8: صيانه دوريه | F8: 48000 | H8: علي غازي
A9: 4 | C9: 9638 | D9: 45900 | E9: دسك امامي+اجور عمل | F9: 110000 | H9: علي غازي
A10: 5 | C10: 9920 | D10: 45931 | E10: تبديل دهن+فلتر+دسكات+اجور عمل | F10: 416000 | H10: علي غازي
A11: 6 | C11: 101 | D11: 18/10/2025 | E11: دهن+فلتر | F11: 95000 | H11: علي غازي
A12: 7 | C12: 343 | D12: 45983 | E12: تبديل دهن+فلتر+دسكات+اجور عمل | F12: 210000 | H12: علي غازي
A13: 6 | C13: 615 | D13: 46018 | E13: اطار+دهن و فلتر | F13: 94000 | G13: 220 | H13: علي غازي
A14: 9 | C14: 1093 | D14: 46086 | E14: دهن+فلاتر+ادامه | F14: 226320 | H14: علي غازي
A15: 10 | C15: 1281 | D15: 18/4/2026 | E15: دسك امامي+تصفير فلنجات+اجور عمل | F15: 150000 | H15: علي غازي
A16: 11
A17: 12
A18: 13
A19: 14
A20: 15
A21: 16
A22: 17
A23: 18
A24: 19
A25: 20
A26: 21
A27: 22
... A109: 104
F110: =SUM(F7:F109) -> 1618320 | G110: =SUM(G7:G109) -> 220

Sheet 2025 تويوتا بكب (2)
A1: صيانة الاليات
A2: 15 | B2: تويوتا هايلوكس دبل كابينة - بيك اب | E2: الموديل | F2: 2025 | H2: الموقع: | K2: رجوع الى جدول الاليات
B3: رقمها : | C3: 11 H 68461 | E3: المالك | F3: القبس | H3: مسؤول الالية :
B5: الشهر | C5: 2025/31/07 | E5: العداد السابق | H5: العداد النهائي : | I5: =MAX(J7:J141) -> 0
A6: # | B6: اسم السائق / المسؤول | C6: رقم الوصل | D6: تاريخ | E6: تفاصيل الصيانه | F6: المبلغ دينار | G6: المبلغ $ | H6: مسؤول الصيانه | I6: اضافة /هايدوليك لتر | J6: العداد
A7: 1
A8: 3
A9: 4
A10: 5
A11: 6
A12: 7
A13: 6
A14: 9
A15: 10
A16: 11
A17: 12
A18: 13
... A99: 94
F100: =SUM(F7:F99) -> 0 | G100: =SUM(G7:G99) -> 0

Sheet 2025 تويوتا بكب (3)
A1: صيانة الاليات
A2: 15 | B2: تويوتا هايلوكس دبل كابينة - بيك اب | E2: الموديل | F2: 2025 | H2: الموقع: | K2: رجوع الى جدول الاليات
B3: رقمها : | C3: 11 H 68461 | E3: المالك | F3: القبس | H3: مسؤول الالية :
B5: الشهر | C5: 2025/31/07 | E5: العداد السابق | H5: العداد النهائي : | I5: =MAX(J7:J141) -> 0
A6: # | B6: اسم السائق / المسؤول | C6: رقم الوصل | D6: تاريخ | E6: تفاصيل الصيانه | F6: المبلغ دينار | G6: المبلغ $ | H6: مسؤول الصيانه | I6: اضافة /هايدوليك لتر | J6: العداد
A7: 1
A8: 3
A9: 4
A10: 5
A11: 6
A12: 7
A13: 6
A14: 9
A15: 10
A16: 11
A17: 12
A18: 13
... A99: 94
F100: =SUM(F7:F99) -> 0 | G100: =SUM(G7:G99) -> 0

Sheet 2025 تويوتا بكب (4)  
A1: صيانة الاليات
A2: 15 | B2: تويوتا هايلوكس دبل كابينة - بيك اب | E2: الموديل | F2: 2025 | H2: الموقع: | K2: رجوع الى جدول الاليات
B3: رقمها : | C3: 11 H 68461 | E3: المالك | F3: القبس | H3: مسؤول الالية :
B5: الشهر | C5: 2025/31/07 | E5: العداد السابق | H5: العداد النهائي : | I5: =MAX(J7:J141) -> 0
A6: # | B6: اسم السائق / المسؤول | C6: رقم الوصل | D6: تاريخ | E6: تفاصيل الصيانه | F6: المبلغ دينار | G6: المبلغ $ | H6: مسؤول الصيانه | I6: اضافة /هايدوليك لتر | J6: العداد
A7: 1
A8: 3
A9: 4
A10: 5
A11: 6
A12: 7
A13: 6
A14: 9
A15: 10
A16: 11
A17: 12
A18: 13
... A99: 94
F100: =SUM(F7:F99) -> 0 | G100: =SUM(G7:G99) -> 0

Sheet تويوتا بكب 49923
A1: صيانة الاليات
A2: 20 | B2: تويوتا هايلوكس دبل كابينة - بيك اب | E2: الموديل | F2: 2009 | H2: الموقع: | K2: رجوع الى جدول الاليات
B3: رقمها : | C3: 49923 أ بغداد | E3: المالك | F3: شركة القبس | H3: مسؤول الالية :
B5: الشهر | C5: 2025/31/07 | E5: العداد السابق | H5: العداد النهائي : | I5: =MAX(J7:J141) -> 0
A6: # | B6: اسم السائق / المسؤول | C6: رقم الوصل | D6: تاريخ | E6: تفاصيل الصيانه | F6: المبلغ دينار | G6: المبلغ $ | H6: مسؤول الصيانه | I6: اضافة /هايدوليك لتر | J6: العداد
A7: 24 | B7: علي غازي | C7: 4266 | D7: 45047 | E7: إطارات | F7: 265000
A8: 25 | C8: 5166 | D8: 44992 | E8: تيب | F8: 80000 | H8: علي غازي
A9: 26 | C9: 5166 | D9: 44992 | E9: صيانة | F9: 190000 | H9: علي غازي
A10: 27 | C10: قيد 97 | D10: 45023 | E10: صيانه | F10: 75000
A11: 28 | C11: 6317 | D11: 23/3/2024 | E11: صيانه | F11: 340000 | H11: علي غازي
A12: 29 | C12: 6381 | D12: 13/4/2024 | E12: صدر امامي خلفي+بنزين+يدة باب +خط جانبي | F12: 1578000 | H12: علي غازي
A13: 30 | C13: 6861 | D13: 45451 | E13: بوش+بريس+اجور عمل+تصليح داينمو | F13: 215000 | H13: علي غازي
A14: 31 | C14: 7071 | D14: 45560 | E14: واشر غطاس+جهاز انذار+فيتبم مع فلتر+اجور عمل | F14: 175000 | H14: علي غازي
A15: 32 | C15: 9450 | D15: 45876 | E15: دسكات امامي+فحص جهاز+غسل+بنجر+جادر | F15: 148000 | H15: شاكر محمود
A16: 33 | C16: 9638 | D16: 45900 | E16: اطارات | F16: 230000 | H16: علي غازي
A17: 34 | C17: 615 | D17: 46018 | E17: دهن+فلتر+لايت+بلوجكترات+شباك امامي | F17: 295000 | H17: علي غازي
A18: 35
A19: 36
A20: 37
A21: 38
A22: 39
A23: 40
A24: 41
A25: 42
A26: 43
A27: 44
A28: 45
A29: 46
... A38: 55
B39: المجموع الكلي | F39: =SUM(F7:F38) -> 3591000 | G39: =SUM(G7:G38) -> 0

Sheet كيا 87740
A1: صيانة الاليات
A2: 21 | B2: كيا دبل قمارة | E2: الموديل | F2: 2019 | H2: الموقع: | K2: رجوع الى جدول الاليات
B3: رقمها : | C3: 11 H 87740 | E3: المالك | F3: شركة القبس | H3: مسؤول الالية :
B5: الشهر | C5: 2025/31/07 | E5: العداد السابق | H5: العداد النهائي : | I5: =MAX(J7:J141) -> 0
A6: # | B6: اسم السائق / المسؤول | C6: رقم الوصل | D6: تاريخ | E6: تفاصيل الصيانه | F6: المبلغ دينار | G6: المبلغ $ | H6: مسؤول الصيانه | I6: اضافة /هايدوليك لتر | J6: العداد
A7: 1 | C7: قيد 15 | D7: 45414 | E7: صيانه | F7: 726000
A8: 2 | C8: 6263 | D8: 45325 | E8: كيلون جامه عدد2 | F8: 80000 | H8: علي غازي
A9: 3 | C9: 6317 | D9: 23/3/2024 | E9: صيانه | F9: 507000 | H9: علي غازي
A10: 4 | C10: 6381 | D10: 13/4/2024 | E10: دعاميه اماميه+لايت+براكيت+ماسكه+ارضيات+كلبسات+غسل كيا+بولش + سمكره | F10: 1010000 | H10: علي غازي
A11: 5 | C11: 6705 | D11: 45329 | E11: تجديد سنويه + غرامه | F11: 505000 | H11: ابومروان
A12: 6 | D12: 45580 | E12: صيانه+كاز | F12: 86000 | H12: علي غازي
A13: 7 | C13: 7272 | D13: 45599 | E13: دهن + فلتر | F13: 45000 | H13: علي غازي
A14: 8 | C14: 7348 | D14: 45619 | E14: زوج اطارات | F14: 165000 | H14: علي غازي
A15: 9 | C15: 7587 | D15: 45650 | E15: دهن+فلتر+غسل +بلك حماوه | F15: 78000 | H15: علي غازي
A16: 10 | C16: 7882 | D16: 45705 | E16: بطاريه | F16: 100000 | H16: علي غازي
A17: 11 | C17: 8062 | D17: 45739 | E17: دعاميه اماميه+مرايات اشاره | F17: 105000 | H17: علي غازي
A18: 12 | C18: 8713 | D18: 45777 | E18: زوج اطارات | F18: 285000 | H18: علي غازي
A19: 13 | C19: 9087 | D19: 45836 | E19: مدكه | F19: 25000 | H19: علي غازي
A20: 14 | C20: 9539 | D20: 45890 | E20: اكسل+دعاميه خلفيه | F20: 320000 | H20: علي غازي
A21: 15 | C21: 303 | D21: 45977 | E21: جامه اماميه | F21: 75000 | H21: علي غازي
A22: 16 | C22: 615 | D22: 46018 | E22: زوج اطارات+دهن وفلتر+سلف كيا | F22: 307000 | H22: علي غازي
A23: 17
B24: المجموع الكلي | F24: =SUM(F7:F23) -> 4419000 | G24: =SUM(G7:G23) -> 0

Sheet كيا 84103
A1: صيانة الاليات
A2: 22 | B2: كيا قمارة | E2: الموديل | F2: 2019 | H2: الموقع: | K2: رجوع الى جدول الاليات
B3: رقمها : | C3: 84103 هـ بغداد | E3: المالك | F3: شركة القبس | H3: مسؤول الالية :
B5: الشهر | C5: 2025/31/07 | E5: العداد السابق | H5: العداد النهائي : | I5: =MAX(J7:J176) -> 0
A6: # | B6: اسم السائق / المسؤول | C6: رقم الوصل | D6: تاريخ | E6: تفاصيل الصيانه | F6: المبلغ دينار | G6: المبلغ $ | H6: مسؤول الصيانه | I6: اضافة /هايدوليك لتر | J6: العداد
A7: 1 | B7: علي غازي | C7: 4266 | D7: 45047 | E7: إطارات | F7: 290000 | H7: علي غازي
A8: 2 | B8: يوسف حسام | D8: 45047 | E8: دهن محرك ,اجور عمل | F8: 45000 | H8: هيلان ابراهيم
A9: 3 | B9: عمر جواد | D9: 6-8-22023 | E9: تبديل دهن + فلتر | F9: 30000 | H9: هيلان ابراهيم
A10: 4 | C10: 4880 | D10: 45082 | E10: بلك حماوه + اجور عمل | F10: 60000 | H10: علي غازي
A11: 5 | C11: 4880 | D11: 45082 | E11: صيانه | F11: 170000 | H11: علي غازي
A12: 6 | C12: 4984 | D12: 27/5/2023 | E12: صيانه | F12: 73000 | H12: علي غازي
A13: 7 | C13: 5596 | D13: 45117 | E13: صيانة | F13: 242000 | H13: علي غازي
A14: 8 | C14: 5666 | D14: 22/10/2023 | E14: صيانة | F14: 299000 | H14: علي غازي
A15: 9 | C15: 6049 | D15: 13/1/2024 | E15: صيانه | F15: 175000 | H15: علي غازي
A16: 10 | C16: 6145 | D16: 31/1/2024 | E16: صيانه | F16: 1910000 | H16: علي غازي
A17: 11 | C17: قيد 8 | D17: 45293 | E17: دهن | F17: 58500
A18: 12 | C18: 6861 | D18: 45451 | E18: اطارات اماميه | F18: 290000 | H18: علي غازي
A19: 13 | C19: 7829 | D19: 45696 | E19: بوش+لاستيك سبرنك+فايرات+اجور عمل | F19: 70000 | H19: علي غازي
A20: 14 | C20: 7882 | D20: 45705 | E20: دسكات+اجور عمل | F20: 70000 | H20: علي غازي
A21: 15 | C21: 8062 | D21: 45739 | E21: اطارات | F21: 335000 | H21: علي غازي
A22: 16 | C22: 8850 | D22: 45798 | E22: تصليح بريك+صليب ستيرن | F22: 393000 | H22: علي غازي
A23: 17 | C23: 8981 | D23: 45813 | E23: زوج اطارات+دهن+جك+حبل | F23: 153000 | H23: علي غازي
A24: 18 | C24: 9087 | D24: 45836 | E24: تبديل فريز+هزاز صالنصه+عمل | F24: 305000 | H24: علي غازي
A25: 19 | C25: 9203 | D25: 45848 | E25: تبديل نوزلات | F25: 410000 | H25: علي غازي
A26: 20 | C26: 9434 | D26: 45874 | E26: قوايش | F26: 67000 | H26: علي غازي
A27: 21
A28: 22
A29: 23
A30: 24
A31: 25
A32: 26
A33: 27
A34: 28
A35: 29
A36: 30
A37: 31
A38: 32
... A66: 60
B67: المجموع الكلي | F67: =SUM(F7:F66) -> 5445500 | G67: =SUM(G7:G66) -> 0

Sheet كيا 87065
A1: صيانة الاليات
A2: 23 | B2: كيا دبل قمارة | E2: الموديل | F2: 2013 | H2: الموقع: | K2: رجوع الى جدول الاليات
B3: رقمها : | C3: 87065 ك بغداد | E3: المالك | F3: شركة القبس | H3: مسؤول الالية :
B5: الشهر | C5: 2025/31/07 | E5: العداد السابق | H5: العداد النهائي : | I5: =MAX(J7:J141) -> 0
A6: # | B6: اسم السائق / المسؤول | C6: رقم الوصل | D6: تاريخ | E6: تفاصيل الصيانه | F6: المبلغ دينار | G6: المبلغ $ | H6: مسؤول الصيانه | I6: اضافة /هايدوليك لتر | J6: العداد
A7: 1 | B7: حسن محمود عيادة | D7: 44934 | E7: اجور تبدل دهن , تدوير اطارت , بلنص | F7: 19000 | H7: هيلان ابراهيم
A8: 2 | B8: حسن محمود عيادة | D8: 44948 | E8: تبدل اطارات + ولف اطار | F8: 10000 | H8: حسن محمود
A9: 3 | B9: حسن محمود عيادة | D9: 44957 | E9: بنز خلفي , عمل تصفير فلنجة , جبنة ويل خلفي صغيرة , كريز , اجرة فيتر | F9: 93000 | H9: هيلان ابراهيم
A10: 4 | B10: يوسف حسام | D10: 45048 | E10: هورن 12 فولت | F10: 20000 | H10: هيلان ابراهيم
A11: 5 | B11: حسن محمود عيادة | D11: 45052 | E11: تبديل عنبار كلج | F11: 20000 | H11: هيلان ابراهيم
A12: 6 | B12: حسن محمود عيادة | D12: 45076 | E12: تعديل ميزانية + بلنص + تدوير اطارات | F12: 9000 | H12: هيلان ابراهيم
A13: 7 | B13: عمر جواد | D13: 45092 | E13: دسك امامي , بولبرن كير , جبنة امامي | F13: 95000 | H13: هيلان ابراهيم
A14: 8 | B14: عمر جواد | D14: 45194 | E14: بولبرن اطار امامي | F14: 20000 | H14: هيلان ابراهيم
A15: 9 | B15: عمر جواد | D15: 45203 | E15: شراء سلف | F15: 80000 | H15: هيلان ابراهيم
A16: 10 | B16: عمر جواد | D16: 45225 | E16: شراء جوين راديتر , شراء دسكات اصلي , تصليح صدر سيارة | F16: 143000 | H16: هيلان ابراهيم
A17: 11 | D17: 45242 | E17: قوايش + رولة + تصفير فلنجة + دسكات + اجور عمل | F17: 100000 | H17: هيلان ابراهيم
A18: 12 | C18: 5922 | D18: 20/12/2023 | E18: اجور عمل تجفيت محرك+بريك+تبديل فيتبم+اجور عمل كور+اجور عمل كهربائي تبديل بلكات حماوه+تبديل داينمو+كيلون بنيد+فان بنكو+نوزلات+صدر+كماليات+تجفيت | F18: 3608000 | H18: علي غازي
A19: 13 | C19: 6145 | D19: 31/1/2024 | E19: غلاف بدي+كهربائيات+كشنات+جاملغات+دعاميه+شباك+ترايش جام+غلاف سماعه+جام امامي+صدر+ربلات+دركة ستيرن+اجور عمل | F19: 2623000 | H19: علي غازي
A20: 14 | C20: 6263 | D20: 45325 | E20: صيانه | F20: 420000 | H20: علي غازي
A21: 15 | C21: 6758 | D21: 14/7/2024 | E21: اطار | F21: 185000 | H21: علي غازي
A22: 16 | C22: 7829 | D22: 45696 | E22: ويل خلفي+اطارات+فلنجات اماميه | F22: 295000 | H22: علي غازي
A23: 17 | C23: 8981 | D23: 45813 | E23: يدة باب | F23: 25000 | H23: علي غازي
A24: 18 | C24: 9539 | D24: 45890 | E24: واير+بوش | F24: 45000 | H24: علي غازي
A25: 19 | C25: 9738 | D25: 45913 | E25: كمبريسر | F25: 200000 | H25: علي غازي
A26: 20
A27: 21
A28: 22
A29: 23
A30: 24
A31: 25
A32: 26
A33: 27
A34: 28
A35: 29
A36: 30
A37: 31
... A78: 72
B79: المجموع الكلي | F79: =SUM(F7:F78) -> 8010000 | G79: =SUM(G7:G78) -> 0

Sheet كيا  68783 
A1: صيانة الاليات
A2: 24 | B2: كيا دبل قمارة | E2: الموديل | F2: 2013 | H2: الموقع: | K2: رجوع الى جدول الاليات
B3: رقمها : | C3: 68783 أ بغداد | E3: المالك | F3: شركة سمو بغداد | H3: مسؤول الالية :
B5: الشهر | C5: 2025/31/07 | E5: العداد السابق | H5: العداد النهائي : | I5: =MAX(J7:J141) -> 0
A6: # | B6: اسم السائق / المسؤول | C6: رقم الوصل | D6: تاريخ | E6: تفاصيل الصيانه | F6: المبلغ دينار | G6: المبلغ $ | H6: مسؤول الصيانه | I6: اضافة /هايدوليك لتر | J6: العداد
A7: 1 | B7: عمر جواد | D7: 45049 | E7: بطل تبريد , ماطور بنكة , غاز , قايش , بخاخ , اجور عمل فيتر | F7: 290000 | H7: هيلان ابراهيم
A8: 2 | B8: عمر جواد | D8: 45074 | E8: تصليح داينمو | F8: 35000 | H8: هيلان ابراهيم
A9: 3 | B9: عمر جواد | D9: 45081 | E9: شريط ستيرن , هورنات, كتف هورن , اجور عمل | F9: 55000 | H9: هيلان ابراهيم
A10: 4 | B10: عمر جواد | D10: 45081 | E10: دشلي , بلاتين , فحمات , اجور عمل | F10: 50000 | H10: هيلان ابراهيم
A11: 5 | B11: عمر جواد | D11: 45088 | E11: شراء داينمو جديد , اجور عمل | F11: 120000 | H11: هيلان ابراهيم
A12: 6 | B12: عمر جواد | D12: 45203 | E12: قرص + عينة + بولبرن | F12: 130000 | H12: هيلان ابراهيم
A13: 7 | B13: عمر جواد | D13: 45223 | E13: تصليح صدر سيارة | F13: 194000 | H13: هيلان ابراهيم
A14: 8 | B14: هيلان ابراهيم | D14: 45276 | E14: شراء تخم جاملغات | F14: 40000 | H14: هيلان ابراهيم
A15: 9 | C15: 4984 | D15: 27/5/2023 | E15: صيانه | F15: 245000 | H15: علي غازي
A16: 10 | C16: 5365 | D16: 45268 | E16: صيانه | G16: 780 | H16: علي غازي
A17: 11 | C17: 5365 | D17: 45268 | E17: صيانه | F17: 363000 | H17: علي غازي
A18: 12 | C18: 7272 | D18: 45599 | E18: اطارات | F18: 190000 | H18: علي غازي
A19: 13 | C19: 8850 | D19: 45798 | E19: زوج اطارات | F19: 270000 | H19: علي غازي
A20: 14 | C20: 1428 | D20: 18/5/2026 | E20: فان كيا | F20: 100000 | H20: علي غازي
A21: 15
A22: 16
A23: 17
A24: 18
A25: 19
A26: 20
A27: 21
A28: 22
A29: 23
A30: 24
A31: 25
A32: 26
... A48: 42
B49: المجموع الكلي | F49: =SUM(F7:F48) -> 2082000 | G49: =SUM(G7:G48) -> 780

Sheet كيا 80540
A1: صيانة الاليات
A2: 25 | B2: كيا قمارة | E2: الموديل | F2: 2012 | H2: الموقع: | K2: رجوع الى جدول الاليات
B3: رقمها : | C3: 80540 و بغداد | E3: المالك | F3: شركة القبس | H3: مسؤول الالية :
B5: الشهر | C5: 2025/31/07 | E5: العداد السابق | H5: العداد النهائي : | I5: =MAX(J7:J141) -> 0
A6: # | B6: اسم السائق / المسؤول | C6: رقم الوصل | D6: تاريخ | E6: تفاصيل الصيانه | F6: المبلغ دينار | G6: المبلغ $ | H6: مسؤول الصيانه | I6: اضافة /هايدوليك لتر | J6: العداد
A7: 1 | B7: علي نادي | D7: 45272 | E7: تبديل دهن , فلتر | F7: 37000 | H7: هيلان ابراهيم
A8: 2 | C8: قيد42 | D8: 28/2/2023 | E8: جامه اماميه | F8: 75000
A9: 3 | C9: 5075 | D9: 45266 | E9: تجديد سنويه | F9: 673000 | H9: ابو مروان
A10: 4 | C10: قيد 97 | D10: 45023 | E10: صيانة تبريد | F10: 730000
A11: 5 | C11: قيد 102 | D11: 23/7/2023 | E11: صيانه | F11: 132000
A12: 6 | C12: 6263 | D12: 45325 | E12: صيانه | F12: 3095000 | H12: علي غازي
A13: 7 | C13: 7587 | D13: 45650 | E13: سلف | F13: 100000 | H13: علي غازي
A14: 8 | C14: 7658 | D14: 45662 | E14: اطارات | F14: 295000 | H14: علي غازي
A15: 9 | C15: 7717 | D15: 45676 | E15: قوايش | F15: 25000 | H15: علي غازي
A16: 10 | C16: 7829 | D16: 45696 | E16: مثلث جامه | F16: 35000 | H16: علي غازي
A17: 11 | C17: 1158 | D17: 18/3/2026 | E17: زوج اطارات+اجور فيتر | F17: 435000 | H17: علي غازي
A18: 12
A19: 13
A20: 14
A21: 15
A22: 16
A23: 17
A24: 18
A25: 19
A26: 20
A27: 21
A28: 22
A29: 23
... A47: 41
B48: المجموع الكلي | F48: =SUM(F7:F47) -> 5632000 | G48: =SUM(G7:G47) -> 0

Sheet كيا 4462
A1: صيانة الاليات
A2: 26 | B2: كيا دبل قمارة | E2: الموديل | F2: 2009 | H2: الموقع: | K2: رجوع الى جدول الاليات
B3: رقمها : | C3: 4462 أ بغداد | E3: المالك | F3: شركة القبس | H3: مسؤول الالية :
B5: الشهر | C5: 2025/31/07 | E5: العداد السابق | H5: العداد النهائي : | I5: =MAX(J7:J230) -> 0
A6: # | B6: اسم السائق / المسؤول | C6: رقم الوصل | D6: تاريخ | E6: تفاصيل الصيانه | F6: المبلغ دينار | G6: المبلغ $ | H6: مسؤول الصيانه | I6: اضافة /هايدوليك لتر | J6: العداد
A7: 1 | B7: مازن سامي | D7: 44929 | E7: فلتر دهن, سي اويل , فلتر كاز , هيدروليم | F7: 14000 | H7: هيلان ابراهيم
A8: 2 | B8: مازن سامي | D8: 44929 | E8: تبديل دهن محرك | F8: 24000 | H8: هيلان ابراهيم
A9: 3 | C9: قيد 97 | D9: 45023 | E9: صيانة | F9: 188000
A10: 4 | C10: 6145 | D10: 31/1/2024 | E10: تجفيت صدر | F10: 485000 | H10: علي غازي
A11: 5 | C11: 6145 | D11: 31/1/2024 | E11: نوزلات+كور+تجفيت محرك+دهن وفلتر+سي اويل+قوايش+تجفيت بم+جوينات ماء+كماليات | F11: 1889000 | H11: علي غازي
A12: 6 | C12: 6263 | D12: 45325 | E12: واشر قبغ ولفات+كرين+ولف حماوه+كيلون+نرماده+قاعدة بلكات | F12: 375000 | H12: علي غازي
A13: 7 | C13: 6317 | D13: 23/3/2024 | E13: دوشمه+شريط جانبي+ارضيات+عمل صالنصه+كهربائيات مع اجور عمل+كماليات | F13: 1357000 | H13: علي غازي
A14: 8 | C14: 6488 | D14: 45601 | E14: اطارات+كماليات | F14: 290000 | H14: علي غازي
A15: 9 | C15: 7580 | D15: 45649 | E15: طبله+دسك | F15: 135000 | H15: علي غازي
A16: 10 | C16: 7587 | D16: 45650 | E16: طبله | F16: 85000 | H16: علي غازي
A17: 11 | C17: 7992 | D17: 45722 | E17: جاملغات+صالنصه | F17: 105000 | H17: علي غازي
A18: 12 | C18: 8152 | D18: 45760 | E18: كلج مروحه+مروحة تبريد | F18: 80000 | H18: علي غازي
A19: 13 | C19: 8850 | D19: 45798 | E19: عمبار كلج | F19: 15000 | H19: علي غازي
A20: 14 | C20: 9738 | D20: 45913 | E20: اطارات | F20: 165000 | H20: علي غازي
A21: 15
A22: 16
A23: 17
A24: 18
A25: 19
A26: 20
A27: 21
A28: 22
A29: 23
A30: 24
A31: 25
A32: 26
... A114: 108
B115: المجموع الكلي | F115: =SUM(F7:F114) -> 5207000 | G115: =SUM(G7:G114) -> 0

Sheet كيا 41711
A1: صيانة الاليات
A2: 27 | B2: كيا دبل قمارة | E2: الموديل | F2: 2019 | H2: الموقع: | K2: رجوع الى جدول الاليات
B3: رقمها : | C3: 41711 ط بغداد | E3: المالك | F3: شركة القبس | H3: مسؤول الالية :
B5: الشهر | C5: 2025/31/07 | E5: العداد السابق | H5: العداد النهائي : | I5: =MAX(J7:J141) -> 0
A6: # | B6: اسم السائق / المسؤول | C6: رقم الوصل | D6: تاريخ | E6: تفاصيل الصيانه | F6: المبلغ دينار | G6: المبلغ $ | H6: مسؤول الصيانه | I6: اضافة /هايدوليك لتر | J6: العداد
A7: 1 | B7: علي غازي | C7: 4266 | D7: 45047 | E7: صيانه | F7: 285000 | H7: علي غازي
A8: 2 | B8: عمر جواد | D8: 45073 | E8: تبديل دهن , فلتر دهن | F8: 60000 | H8: هيلان ابراهيم
A9: 3 | B9: عمر جواد | D9: 45173 | E9: تبديل دهن , فلتر , صبغ دعامية خلفية | F9: 110500 | H9: هيلان ابراهيم
A10: 4 | B10: عمر جواد | D10: 45241 | E10: تبديل دهن + فلاتر | F10: 42000 | H10: هيلان ابراهيم
A11: 5 | C11: 5122 | D11: 21/6/2023 | E11: اطارات | F11: 200000 | H11: علي غازي
A12: 6 | C12: قيد 97 | D12: 45023 | E12: صيانة تبريد | F12: 64000
A13: 7 | C13: قيد 102 | D13: 23/7/2023 | E13: صيانه | F13: 115000
A14: 8 | C14: قيد 102 | D14: 23/7/2023 | E14: صيانه | F14: 94000
A15: 9 | C15: قيد 128 | D15: 45270 | E15: دهن + غسل | F15: 35000
A16: 10 | C16: قيد 131 | D16: 22/10/2023 | E16: بنكة تبريد | F16: 78000
A17: 11 | C17: قيد 135 | D17: 45149 | E17: براغي صالنصه | F17: 33000
A18: 12 | C18: 6049 | D18: 13/1/2024 | E18: بطاريه | F18: 75000 | H18: علي غازي
A19: 13 | C19: 7430 | D19: 45631 | E19: دهن + فلتر+ غسل وتشحيم | F19: 48000 | H19: علي غازي
A20: 14 | C20: 8062 | D20: 45739 | E20: فريز+راديتر+هورن+قوايش+روله+عنبار+صليب طويل و قصير+دعاميه و براكيت+ماسكه+بروجكتور+غلاف ستيرن+اجور عمل | F20: 1028000 | H20: علي غازي
A21: 15 | C21: 8806 | D21: 45791 | E21: زوج اطارات | F21: 170000 | H21: علي غازي
A22: 16 | C22: 8981 | D22: 45813 | E22: زوج اطارات | F22: 190000 | H22: علي غازي
A23: 17 | C23: 960 | D23: 46358 | E23: بنيد | F23: 250000 | H23: علي غازي
A24: 18 | C24: 1093 | D24: 46086 | E24: شريط دبل قماره | F24: 50000 | H24: علي غازي
A25: 19 | C25: 1281 | D25: 18/4/2026 | E25: ماطور بنكو | F25: 25000 | H25: علي غازي
A26: 20 | C26: 1394 | D26: 46300 | E26: زوج اطارات | F26: 260000 | H26: علي غازي
A27: 21 | C27: 1428 | D27: 18/5/2026 | E27: دسكات | F27: 20000 | H27: علي غازي
A28: 22
A29: 23
A30: 24
A31: 25
A32: 26
A33: 27
A34: 28
A35: 29
A36: 30
A37: 31
A38: 32
A39: 33
... A46: 40
B47: المجموع الكلي | F47: =SUM(F7:F46) -> 3232500 | G47: =SUM(G7:G46) -> 0

Sheet كيا 46696
A1: صيانة الاليات
A2: 28 | B2: كيا دبل قمارة | E2: الموديل | F2: 2013 | H2: الموقع: | K2: رجوع الى جدول الاليات
B3: رقمها : | C3: 46696 هـ بغداد | E3: المالك | F3: شركة القبس | H3: مسؤول الالية :
B5: الشهر | C5: 2025/31/07 | E5: العداد السابق | H5: العداد النهائي : | I5: =MAX(J7:J141) -> 0
A6: # | B6: اسم السائق / المسؤول | C6: رقم الوصل | D6: تاريخ | E6: تفاصيل الصيانه | F6: المبلغ دينار | G6: المبلغ $ | H6: مسؤول الصيانه | I6: اضافة /هايدوليك لتر | J6: العداد
A7: 1 | C7: قيد 43 | D7: 45019 | E7: دهن و فلتر | F7: 35000
A8: 2 | C8: 5122 | D8: 21/6/2023 | E8: اطارات | F8: 75000 | H8: علي غازي
